[2024-06-02T23:16:10.379+0000] {task_context_logger.py:104} ERROR - Executor reports task instance <TaskInstance: AAAA.task_1 manual__2024-06-02T23:15:01.636310+00:00 [queued]> finished (failed) although the task says it's queued. (Info: None) Was the task killed externally?
